<?xml version="1.0" encoding="utf-8"?>
<!-- This URDF was automatically created by SolidWorks to URDF Exporter! Originally created by Stephen Brawner (brawner@gmail.com) 
     Commit Version: 1.6.0-4-g7f85cfe  Build Version: 1.6.7995.38578
     For more information, please see http://wiki.ros.org/sw_urdf_exporter -->
<robot
  name="gagah_ganteng">
  <link
    name="base_link">
    <inertial>
      <origin
        xyz="0.0095865 0.0064859 0.039653"
        rpy="0 0 0" />
      <mass
        value="3.5" />
      <inertia
        ixx="0.00417"
        ixy="-0.00032831"
        ixz="0.00062645"
        iyy="0.012777"
        iyz="0.00058894"
        izz="0.01649" />
    </inertial>
    <visual>
      <origin
        xyz="0 0 0"
        rpy="0 0 0" />
      <geometry>
        <mesh
          filename="package://gagah_ganteng/meshes/base_link.STL" />
      </geometry>
      <material
        name="">
        <color
          rgba="0.79216 0.81961 0.93333 1" />
      </material>
    </visual>
    <collision>
      <origin
        xyz="0 0 0"
        rpy="0 0 0" />
      <geometry>
        <mesh
          filename="package://gagah_ganteng/meshes/base_link.STL" />
      </geometry>
    </collision>
  </link>
  <link
    name="lower_right_wheel_Link">
    <inertial>
      <origin
        xyz="-7.0204E-08 0.023421 -7.567E-08"
        rpy="0 0 0" />
      <mass
        value="0.5" />
      <inertia
        ixx="4.6952E-05"
        ixy="5.489E-18"
        ixz="8.5235E-18"
        iyy="6.4174E-05"
        iyz="6.7947E-18"
        izz="4.6952E-05" />
    </inertial>
    <visual>
      <origin
        xyz="0 0 0"
        rpy="0 0 0" />
      <geometry>
        <mesh
          filename="package://gagah_ganteng/meshes/lower_right_wheel_Link.STL" />
      </geometry>
      <material
        name="">
        <color
          rgba="0.79216 0.81961 0.93333 1" />
      </material>
    </visual>
    <collision>
      <origin
        xyz="0 0 0"
        rpy="0 0 0" />
      <geometry>
        <mesh
          filename="package://gagah_ganteng/meshes/lower_right_wheel_Link.STL" />
      </geometry>
    </collision>
  </link>
  <joint
    name="lower_right_wheel_joint"
    type="continuous">
    <origin
      xyz="-0.18949 -0.18623 0.058954"
      rpy="-0.14648 0.060459 0.040985" />
    <parent
      link="base_link" />
    <child
      link="lower_right_wheel_Link" />
    <axis
      xyz="0 1 0" />
  </joint>
  <link
    name="upper_right_wheel_link">
    <inertial>
      <origin
        xyz="-7.5921E-08 0.023829 6.9932E-08"
        rpy="0 0 0" />
      <mass
        value="0.5" />
      <inertia
        ixx="4.6952E-05"
        ixy="-5.9903E-18"
        ixz="-1.1372E-17"
        iyy="6.4174E-05"
        iyz="6.3402E-18"
        izz="4.6952E-05" />
    </inertial>
    <visual>
      <origin
        xyz="0 0 0"
        rpy="0 0 0" />
      <geometry>
        <mesh
          filename="package://gagah_ganteng/meshes/upper_right_wheel_link.STL" />
      </geometry>
      <material
        name="">
        <color
          rgba="0.79216 0.81961 0.93333 1" />
      </material>
    </visual>
    <collision>
      <origin
        xyz="0 0 0"
        rpy="0 0 0" />
      <geometry>
        <mesh
          filename="package://gagah_ganteng/meshes/upper_right_wheel_link.STL" />
      </geometry>
    </collision>
  </link>
  <joint
    name="upper_right_wheel_joint"
    type="continuous">
    <origin
      xyz="0.2096 -0.1694 0.037911"
      rpy="-0.14732 0.12246 0.031775" />
    <parent
      link="base_link" />
    <child
      link="upper_right_wheel_link" />
    <axis
      xyz="0 1 0" />
  </joint>
  <link
    name="upper_left_wheel_Link">
    <inertial>
      <origin
        xyz="7.9687E-08 -0.023829 -6.561E-08"
        rpy="0 0 0" />
      <mass
        value="0.5" />
      <inertia
        ixx="4.6952E-05"
        ixy="-7.126E-18"
        ixz="-6.2312E-18"
        iyy="6.4174E-05"
        iyz="5.0581E-18"
        izz="4.6952E-05" />
    </inertial>
    <visual>
      <origin
        xyz="0 0 0"
        rpy="0 0 0" />
      <geometry>
        <mesh
          filename="package://gagah_ganteng/meshes/upper_left_wheel_Link.STL" />
      </geometry>
      <material
        name="">
        <color
          rgba="0.79216 0.81961 0.93333 1" />
      </material>
    </visual>
    <collision>
      <origin
        xyz="0 0 0"
        rpy="0 0 0" />
      <geometry>
        <mesh
          filename="package://gagah_ganteng/meshes/upper_left_wheel_Link.STL" />
      </geometry>
    </collision>
  </link>
  <joint
    name="upper_left_wheel_joint"
    type="continuous">
    <origin
      xyz="0.19151 0.19274 -0.015485"
      rpy="-0.14726 0.11895 0.032299" />
    <parent
      link="base_link" />
    <child
      link="upper_left_wheel_Link" />
    <axis
      xyz="0 -1 0" />
  </joint>
  <link
    name="lower_left_wheel_Link">
    <inertial>
      <origin
        xyz="1.6966E-08 -0.023829 -1.0182E-07"
        rpy="0 0 0" />
      <mass
        value="0.5" />
      <inertia
        ixx="4.6952E-05"
        ixy="-2.0206E-18"
        ixz="-2.0441E-17"
        iyy="6.4174E-05"
        iyz="8.5107E-18"
        izz="4.6952E-05" />
    </inertial>
    <visual>
      <origin
        xyz="0 0 0"
        rpy="0 0 0" />
      <geometry>
        <mesh
          filename="package://gagah_ganteng/meshes/lower_left_wheel_Link.STL" />
      </geometry>
      <material
        name="">
        <color
          rgba="0.79216 0.81961 0.93333 1" />
      </material>
    </visual>
    <collision>
      <origin
        xyz="0 0 0"
        rpy="0 0 0" />
      <geometry>
        <mesh
          filename="package://gagah_ganteng/meshes/lower_left_wheel_Link.STL" />
      </geometry>
    </collision>
  </link>
  <joint
    name="lower_left_wheel_joint"
    type="continuous">
    <origin
      xyz="-0.20758 0.17591 0.0055581"
      rpy="-0.14628 -0.031085 0.054479" />
    <parent
      link="base_link" />
    <child
      link="lower_left_wheel_Link" />
    <axis
      xyz="0 -1 0" />
  </joint>
</robot>